<?xml version="1.0"?>
<robot name="spider">
	<link name="body">
		<inertial>
			<mass value="1"/>
      <origin rpy="0  0  0" xyz="0  0  0"/>
      <inertia ixx="0.166667" ixy="0" ixz="0" iyy="0.166667" iyz="0" izz="0.166667"/>
		</inertial>
		<collision name="body_collision">
			<origin rpy="0  0  0" xyz="0  0  0"/>
      <geometry>
        <box size="2 1 0.4"/>
      </geometry>
		</collision>
		<visual name="body_visual">
			<origin rpy="0  0  0" xyz="0  0  0"/>
      <geometry>
        <box size="2 1 0.4"/>
      </geometry>
		</visual>
	</link>
	<link name="head2">
		<inertial>
      <mass value="1"/>
      <origin rpy="0  0  0" xyz="0  0  0"/>
      <inertia ixx="0.166667" ixy="0" ixz="0" iyy="0.166667" iyz="0" izz="0.166667"/>
    </inertial>
    <collision name="head2_collision">
      <origin rpy="0  0  0" xyz="0.8 0 0.3"/>
      <geometry>
        <box size="0.2 0.2 0.2"/>
      </geometry>
    </collision>
    <visual name="head2_visual">
      <origin rpy="0  0  0" xyz="0.8 0 -0.3"/>
      <geometry>
        <box size="0.2 0.2 0.2"/>
      </geometry>
    </visual>
	</link>
	<link name="head">
		<inertial>
      <mass value="1"/>
      <origin rpy="0  0  0" xyz="0  0  0"/>
      <inertia ixx="0.166667" ixy="0" ixz="0" iyy="0.166667" iyz="0" izz="0.166667"/>
    </inertial>
    <collision name="head_collision">
      <origin rpy="0  0  0" xyz="0.8 0 0.3"/>
      <geometry>
        <box size="0.2 0.2 0.2"/>
      </geometry>
    </collision>
    <visual name="head_visual">
      <origin rpy="0  0  0" xyz="0.8 0 0.3"/>
      <geometry>
        <box size="0.2 0.2 0.2"/>
      </geometry>
    </visual>
	</link>
	<link name="left-front-thigh">
		<inertial>
			<mass value="1"/>
			<origin rpy="0 0 0" xyz="0 0 0"/>
			<inertia ixx="0.145833" ixy="0" ixz="0" iyy="0.145833" iyz="0" izz="0.125"/>
		</inertial>
		<collision name="left-front-thigh_collision">
			<origin rpy="-1.57 0 0" xyz="0.75 1 0"/>
			<geometry>
				<cylinder radius="0.1" length="1"/>
			</geometry>
		</collision>
		<visual name="left-front-thigh_visual">
			<origin rpy="-1.57 0 0" xyz="0.75 1 0"/>
			<geometry>
				<cylinder radius="0.1" length="1"/>
			</geometry>
		</visual>
	</link>
	<link name="left-front-shank">
		<inertial>
			<mass value="1"/>
			<origin rpy="0 0 0" xyz="0 0 0"/>
			<inertia ixx="0.145833" ixy="0" ixz="0" iyy="0.145833" iyz="0" izz="0.125"/>
		</inertial>
		<collision name="left-front-shank_collision">
			<origin rpy="0 0 0" xyz="0.75 1.5 -0.5"/>
			<geometry>
				<cylinder radius="0.1" length="1"/>
			</geometry>
		</collision>
		<visual name="left-front-shank_visual">
			<origin rpy="0 0 0" xyz="0.75 1.5 -0.5"/>
			<geometry>
				<cylinder radius="0.1" length="1"/>
			</geometry>
		</visual>
	</link>
	<link name="left-front-foot">
		<inertial>
			<mass value="1"/>
			<origin rpy="0 0 0" xyz="0 0 0"/>
			<inertia ixx="0.166667" ixy="0" ixz="0" iyy="0.166667" iyz="0" izz="0.166667"/>
		</inertial>
		<collision name="left-front-foot_collision">
			<origin rpy="0 0 0" xyz="0.75 1.5 -1.025"/>
			<geometry>
				<box size="0.2 0.6 0.05"/>
			</geometry>
		</collision>
		<visual name="left-front-foot_visual">
			<origin rpy="0 0 0" xyz="0.75 1.5 -1.025"/>
			<geometry>
				<box size="0.2 0.6 0.05"/>
			</geometry>
		</visual>
	</link>
	<link name="left-middle-thigh">
		<inertial>
			<mass value="1"/>
			<origin rpy="0 0 0" xyz="0 0 0"/>
			<inertia ixx="0.145833" ixy="0" ixz="0" iyy="0.145833" iyz="0" izz="0.125"/>
		</inertial>
		<collision name="left-middle-thigh_collision">
			<origin rpy="-1.05 0 0" xyz="0 0.933 0.25"/>
			<geometry>
				<cylinder radius="0.1" length="1"/>
			</geometry>
		</collision>
		<visual name="left-middle-thigh_visual">
			<origin rpy="-1.05 0 0" xyz="0 0.933 0.25"/>
			<geometry>
				<cylinder radius="0.1" length="1"/>
			</geometry>
		</visual>
	</link>
	<link name="left-middle-shank">
		<inertial>
			<mass value="1"/>
			<origin rpy="0 0 0" xyz="0 0 0"/>
			<inertia ixx="0.145833" ixy="0" ixz="0" iyy="0.145833" iyz="0" izz="0.125"/>
		</inertial>
		<collision name="left-middle-shank_collision">
			<origin rpy="0 0 0" xyz="0 1.366 0"/>
			<geometry>
				<cylinder radius="0.1" length="1"/>
			</geometry>
		</collision>
		<visual name="left-middle-shank_visual">
			<origin rpy="0 0 0" xyz="0 1.366 0"/>
			<geometry>
				<cylinder radius="0.1" length="1"/>
			</geometry>
		</visual>
	</link>
	<link name="left-middle-foot">
		<inertial>
			<mass value="1"/>
			<origin rpy="0 0 0" xyz="0 0 0"/>
			<inertia ixx="0.166667" ixy="0" ixz="0" iyy="0.166667" iyz="0" izz="0.166667"/>
		</inertial>
		<collision name="left-middle-foot_collision">
			<origin rpy="0 0 0" xyz="0 1.366 -0.525"/>
			<geometry>
				<box size="0.2 0.6 0.05"/>
			</geometry>
		</collision>
		<visual name="left-middle-foot_visual">
			<origin rpy="0 0 0" xyz="0 1.366 -0.525"/>
			<geometry>
				<box size="0.2 0.6 0.05"/>
			</geometry>
		</visual>
	</link>
	<link name="left-back-thigh">
		<inertial>
			<mass value="1"/>
			<origin rpy="0 0 0" xyz="0 0 0"/>
			<inertia ixx="0.145833" ixy="0" ixz="0" iyy="0.145833" iyz="0" izz="0.125"/>
		</inertial>
		<collision name="left-back-thigh_collision">
			<origin rpy="-1.57 0 0" xyz="-0.75 1 0"/>
			<geometry>
				<cylinder radius="0.1" length="1"/>
			</geometry>
		</collision>
		<visual name="left-back-thigh_visual">
			<origin rpy="-1.57 0 0" xyz="-0.75 1 0"/>
			<geometry>
				<cylinder radius="0.1" length="1"/>
			</geometry>
		</visual>
	</link>
	<link name="left-back-shank">
		<inertial>
			<mass value="1"/>
			<origin rpy="0 0 0" xyz="0 0 0"/>
			<inertia ixx="0.145833" ixy="0" ixz="0" iyy="0.145833" iyz="0" izz="0.125"/>
		</inertial>
		<collision name="left-back-shank_collision">
			<origin rpy="0 0 0" xyz="-0.75 1.5 -0.5"/>
			<geometry>
				<cylinder radius="0.1" length="1"/>
			</geometry>
		</collision>
		<visual name="left-back-shank_visual">
			<origin rpy="0 0 0" xyz="-0.75 1.5 -0.5"/>
			<geometry>
				<cylinder radius="0.1" length="1"/>
			</geometry>
		</visual>
	</link>
	<link name="left-back-foot">
		<inertial>
			<mass value="1"/>
			<origin rpy="0 0 0" xyz="0 0 0"/>
			<inertia ixx="0.166667" ixy="0" ixz="0" iyy="0.166667" iyz="0" izz="0.166667"/>
		</inertial>
		<collision name="left-back-foot_collision">
			<origin rpy="0 0 0" xyz="-0.75 1.5 -1.025"/>
			<geometry>
				<box size="0.2 0.6 0.05"/>
			</geometry>
		</collision>
		<visual name="left-back-foot_visual">
			<origin rpy="0 0 0" xyz="-0.75 1.5 -1.025"/>
			<geometry>
				<box size="0.2 0.6 0.05"/>
			</geometry>
		</visual>
	</link>
	<link name="right-front-thigh">
		<inertial>
			<mass value="1"/>
			<origin rpy="0 0 0" xyz="0 0 0"/>
			<inertia ixx="0.145833" ixy="0" ixz="0" iyy="0.145833" iyz="0" izz="0.125"/>
		</inertial>
		<collision name="right-front-thigh_collision">
			<origin rpy="-2.09 0 0" xyz="0.75 -0.933 0.25"/>
			<geometry>
				<cylinder radius="0.1" length="1"/>
			</geometry>
		</collision>
		<visual name="right-front-thigh_visual">
			<origin rpy="-2.09 0 0" xyz="0.75 -0.933 0.25"/>
			<geometry>
				<cylinder radius="0.1" length="1"/>
			</geometry>
		</visual>
	</link>
	<link name="right-front-shank">
		<inertial>
			<mass value="1"/>
			<origin rpy="0 0 0" xyz="0 0 0"/>
			<inertia ixx="0.145833" ixy="0" ixz="0" iyy="0.145833" iyz="0" izz="0.125"/>
		</inertial>
		<collision name="right-front-shank_collision">
			<origin rpy="0 0 0" xyz="0.75 -1.366 0"/>
			<geometry>
				<cylinder radius="0.1" length="1"/>
			</geometry>
		</collision>
		<visual name="right-front-shank_visual">
			<origin rpy="0 0 0" xyz="0.75 -1.366 0"/>
			<geometry>
				<cylinder radius="0.1" length="1"/>
			</geometry>
		</visual>
	</link>
	<link name="right-front-foot">
		<inertial>
			<mass value="1"/>
			<origin rpy="0 0 0" xyz="0 0 0"/>
			<inertia ixx="0.166667" ixy="0" ixz="0" iyy="0.166667" iyz="0" izz="0.166667"/>
		</inertial>
		<collision name="right-front-foot_collision">
			<origin rpy="0 0 0" xyz="0.75 -1.366 -0.525"/>
			<geometry>
				<box size="0.2 0.6 0.05"/>
			</geometry>
		</collision>
		<visual name="right-front-foot_visual">
			<origin rpy="0 0 0" xyz="0.75 -1.366 -0.525"/>
			<geometry>
				<box size="0.2 0.6 0.05"/>
			</geometry>
		</visual>
	</link>
	<link name="right-middle-thigh">
		<inertial>
			<mass value="1"/>
			<origin rpy="0 0 0" xyz="0 0 0"/>
			<inertia ixx="0.145833" ixy="0" ixz="0" iyy="0.145833" iyz="0" izz="0.125"/>
		</inertial>
		<collision name="right-middle-thigh_collision">
			<origin rpy="-1.57 0 0" xyz="0 -1 0"/>
			<geometry>
				<cylinder radius="0.1" length="1"/>
			</geometry>
		</collision>
		<visual name="right-middle-thigh_visual">
			<origin rpy="-1.57 0 0" xyz="0 -1 0"/>
			<geometry>
				<cylinder radius="0.1" length="1"/>
			</geometry>
		</visual>
	</link>
	<link name="right-middle-shank">
		<inertial>
			<mass value="1"/>
			<origin rpy="0 0 0" xyz="0 0 0"/>
			<inertia ixx="0.145833" ixy="0" ixz="0" iyy="0.145833" iyz="0" izz="0.125"/>
		</inertial>
		<collision name="right-middle-shank_collision">
			<origin rpy="0 0 0" xyz="0 -1.5 -0.5"/>
			<geometry>
				<cylinder radius="0.1" length="1"/>
			</geometry>
		</collision>
		<visual name="right-middle-shank_visual">
			<origin rpy="0 0 0" xyz="0 -1.5 -0.5"/>
			<geometry>
				<cylinder radius="0.1" length="1"/>
			</geometry>
		</visual>
	</link>
	<link name="right-middle-foot">
		<inertial>
			<mass value="1"/>
			<origin rpy="0 0 0" xyz="0 0 0"/>
			<inertia ixx="0.166667" ixy="0" ixz="0" iyy="0.166667" iyz="0" izz="0.166667"/>
		</inertial>
		<collision name="right-middle-foot_collision">
			<origin rpy="0 0 0" xyz="0 -1.5 -1.025"/>
			<geometry>
				<box size="0.2 0.6 0.05"/>
			</geometry>
		</collision>
		<visual name="right-middle-foot_visual">
			<origin rpy="0 0 0" xyz="0 -1.5 -1.025"/>
			<geometry>
				<box size="0.2 0.6 0.05"/>
			</geometry>
		</visual>
	</link>
	<link name="right-back-thigh">
		<inertial>
			<mass value="1"/>
			<origin rpy="0 0 0" xyz="0 0 0"/>
			<inertia ixx="0.145833" ixy="0" ixz="0" iyy="0.145833" iyz="0" izz="0.125"/>
		</inertial>
		<collision name="right-back-thigh_collision">
			<origin rpy="-2.09 0 0" xyz="-0.75 -0.933 0.25"/>
			<geometry>
				<cylinder radius="0.1" length="1"/>
			</geometry>
		</collision>
		<visual name="right-back-thigh_visual">
			<origin rpy="-2.09 0 0" xyz="-0.75 -0.933 0.25"/>
			<geometry>
				<cylinder radius="0.1" length="1"/>
			</geometry>
		</visual>
	</link>
	<link name="right-back-shank">
		<inertial>
			<mass value="1"/>
			<origin rpy="0 0 0" xyz="0 0 0"/>
			<inertia ixx="0.145833" ixy="0" ixz="0" iyy="0.145833" iyz="0" izz="0.125"/>
		</inertial>
		<collision name="right-back-shank_collision">
			<origin rpy="0 0 0" xyz="-0.75 -1.366 0"/>
			<geometry>
				<cylinder radius="0.1" length="1"/>
			</geometry>
		</collision>
		<visual name="right-back-shank_visual">
			<origin rpy="0 0 0" xyz="-0.75 -1.366 0"/>
			<geometry>
				<cylinder radius="0.1" length="1"/>
			</geometry>
		</visual>
	</link>
	<link name="right-back-foot">
		<inertial>
			<mass value="1"/>
			<origin rpy="0 0 0" xyz="0 0 0"/>
			<inertia ixx="0.166667" ixy="0" ixz="0" iyy="0.166667" iyz="0" izz="0.166667"/>
		</inertial>
		<collision name="right-back-foot_collision">
			<origin rpy="0 0 0" xyz="-0.75 -1.366 -0.525"/>
			<geometry>
				<box size="0.2 0.6 0.05"/>
			</geometry>
		</collision>
		<visual name="right-back-foot_visual">
			<origin rpy="0 0 0" xyz="-0.75 -1.366 -0.525"/>
			<geometry>
				<box size="0.2 0.6 0.05"/>
			</geometry>
		</visual>
	</link>
	<joint name="neck" type="fixed">
		<parent link="body"/>
		<child link="head"/>
		<origin rpy="0 0 0" xyz="0 0 0"/>
		<axis xyz="1 0 0"/>
		<limit effort="0" lower="0" upper="0" velocity="0"/>
	</joint>
	<joint name="left-front-coxae" type="continuous">
		<parent link="body"/>
		<child link="left-front-thigh"/>
		<origin rpy="0 0 0" xyz="0 0 0"/>
		<axis xyz="1 0 0"/>
		<limit effort="0" lower="0" upper="0" velocity="0"/>
	</joint>
	<joint name="left-front-knee" type="continuous">
		<parent link="left-front-thigh"/>
		<child link="left-front-shank"/>
		<origin rpy="0 0 0" xyz="0 0 0"/>
		<axis xyz="1 0 0"/>
		<limit effort="0" lower="0" upper="0" velocity="0"/>
	</joint>
	<joint name="left-front-ankle" type="continuous">
		<parent link="left-front-shank"/>
		<child link="left-front-foot"/>
		<origin rpy="0 0 0" xyz="0 0 0"/>
		<axis xyz="1 0 0"/>
		<limit effort="0" lower="0" upper="0" velocity="0"/>
	</joint>
	<joint name="left-middle-coxae" type="continuous">
		<parent link="body"/>
		<child link="left-middle-thigh"/>
		<origin rpy="0 0 0" xyz="0 0 0"/>
		<axis xyz="1 0 0"/>
		<limit effort="0" lower="0" upper="0" velocity="0"/>
	</joint>
	<joint name="left-middle-knee" type="continuous">
		<parent link="left-middle-thigh"/>
		<child link="left-middle-shank"/>
		<origin rpy="0 0 0" xyz="0 0 0"/>
		<axis xyz="1 0 0"/>
		<limit effort="0" lower="0" upper="0" velocity="0"/>
	</joint>
	<joint name="left-middle-ankle" type="continuous">
		<parent link="left-middle-shank"/>
		<child link="left-middle-foot"/>
		<origin rpy="0 0 0" xyz="0 0 0"/>
		<axis xyz="1 0 0"/>
		<limit effort="0" lower="0" upper="0" velocity="0"/>
	</joint><joint name="left-back-coxae" type="continuous">
		<parent link="body"/>
		<child link="left-back-thigh"/>
		<origin rpy="0 0 0" xyz="0 0 0"/>
		<axis xyz="1 0 0"/>
		<limit effort="0" lower="0" upper="0" velocity="0"/>
	</joint>
	<joint name="left-back-knee" type="continuous">
		<parent link="left-back-thigh"/>
		<child link="left-back-shank"/>
		<origin rpy="0 0 0" xyz="0 0 0"/>
		<axis xyz="1 0 0"/>
		<limit effort="0" lower="0" upper="0" velocity="0"/>
	</joint>
	<joint name="left-back-ankle" type="continuous">
		<parent link="left-back-shank"/>
		<child link="left-back-foot"/>
		<origin rpy="0 0 0" xyz="0 0 0"/>
		<axis xyz="1 0 0"/>
		<limit effort="0" lower="0" upper="0" velocity="0"/>
	</joint>
	<joint name="right-front-coxae" type="continuous">
		<parent link="body"/>
		<child link="right-front-thigh"/>
		<origin rpy="0 0 0" xyz="0 0 0"/>
		<axis xyz="1 0 0"/>
		<limit effort="0" lower="0" upper="0" velocity="0"/>
	</joint>
	<joint name="right-front-knee" type="continuous">
		<parent link="right-front-thigh"/>
		<child link="right-front-shank"/>
		<origin rpy="0 0 0" xyz="0 0 0"/>
		<axis xyz="1 0 0"/>
		<limit effort="0" lower="0" upper="0" velocity="0"/>
	</joint>
	<joint name="right-front-ankle" type="continuous">
		<parent link="right-front-shank"/>
		<child link="right-front-foot"/>
		<origin rpy="0 0 0" xyz="0 0 0"/>
		<axis xyz="1 0 0"/>
		<limit effort="0" lower="0" upper="0" velocity="0"/>
	</joint>
	<joint name="right-middle-coxae" type="continuous">
		<parent link="body"/>
		<child link="right-middle-thigh"/>
		<origin rpy="0 0 0" xyz="0 0 0"/>
		<axis xyz="1 0 0"/>
		<limit effort="0" lower="0" upper="0" velocity="0"/>
	</joint>
	<joint name="right-middle-knee" type="continuous">
		<parent link="right-middle-thigh"/>
		<child link="right-middle-shank"/>
		<origin rpy="0 0 0" xyz="0 0 0"/>
		<axis xyz="1 0 0"/>
		<limit effort="0" lower="0" upper="0" velocity="0"/>
	</joint>
	<joint name="right-middle-ankle" type="continuous">
		<parent link="right-middle-shank"/>
		<child link="right-middle-foot"/>
		<origin rpy="0 0 0" xyz="0 0 0"/>
		<axis xyz="1 0 0"/>
		<limit effort="0" lower="0" upper="0" velocity="0"/>
	</joint><joint name="right-back-coxae" type="continuous">
		<parent link="body"/>
		<child link="right-back-thigh"/>
		<origin rpy="0 0 0" xyz="0 0 0"/>
		<axis xyz="1 0 0"/>
		<limit effort="0" lower="0" upper="0" velocity="0"/>
	</joint>
	<joint name="right-back-knee" type="continuous">
		<parent link="right-back-thigh"/>
		<child link="right-back-shank"/>
		<origin rpy="0 0 0" xyz="0 0 0"/>
		<axis xyz="1 0 0"/>
		<limit effort="0" lower="0" upper="0" velocity="0"/>
	</joint>
	<joint name="right-back-ankle" type="continuous">
		<parent link="right-back-shank"/>
		<child link="right-back-foot"/>
		<origin rpy="0 0 0" xyz="0 0 0"/>
		<axis xyz="1 0 0"/>
		<limit effort="0" lower="0" upper="0" velocity="0"/>
	</joint>
	<joint name="neck2" type="fixed">
		<parent link="body"/>
		<child link="head2"/>
		<origin rpy="0 0 0" xyz="0 0 0"/>
		<axis xyz="1 0 0"/>
		<limit effort="0" lower="0" upper="0" velocity="0"/>
	</joint>
</robot>
